<?xml version="1.0" encoding="utf-8"?>
<!-- This URDF was automatically created by SolidWorks to URDF Exporter! Originally created by Stephen Brawner (brawner@gmail.com) 
     Commit Version: 1.5.1-0-g916b5db  Build Version: 1.5.7152.31018
     For more information, please see http://wiki.ros.org/sw_urdf_exporter -->
<robot
  name="threewheel">
  <link
    name="base_link">
    <inertial>
      <origin
        xyz="0.10888 0.081496 -0.14241"
        rpy="0 0 0" />
      <mass
        value="5.3294" />
      <inertia
        ixx="0.021938"
        ixy="-4.0175E-06"
        ixz="-1.4796E-06"
        iyy="0.023203"
        iyz="-7.8034E-06"
        izz="0.014905" />
    </inertial>
    <visual>
      <origin
        xyz="0 0 0"
        rpy="0 0 0" />
      <geometry>
        <mesh
          filename="package://threewheel/meshes/base_link.STL" />
      </geometry>
      <material
        name="">
        <color
          rgba="0.75294 0.75294 0.75294 1" />
      </material>
    </visual>
    <collision>
      <origin
        xyz="0 0 0"
        rpy="0 0 0" />
      <geometry>
        <mesh
          filename="package://threewheel/meshes/base_link.STL" />
      </geometry>
    </collision>
  </link>
  <link
    name="LFS">
    <inertial>
      <origin
        xyz="0.066688 0.0036428 -0.064837"
        rpy="0 0 0" />
      <mass
        value="0.26437" />
      <inertia
        ixx="3.2075E-05"
        ixy="-1.4412E-07"
        ixz="-6.3085E-08"
        iyy="6.227E-05"
        iyz="-2.0189E-07"
        izz="6.2852E-05" />
    </inertial>
    <visual>
      <origin
        xyz="0 0 0"
        rpy="0 0 0" />
      <geometry>
        <mesh
          filename="package://threewheel/meshes/LFS.STL" />
      </geometry>
      <material
        name="">
        <color
          rgba="0.75294 0.75294 0.75294 1" />
      </material>
    </visual>
    <collision>
      <origin
        xyz="0 0 0"
        rpy="0 0 0" />
      <geometry>
        <mesh
          filename="package://threewheel/meshes/LFS.STL" />
      </geometry>
    </collision>
  </link>
  <joint
    name="LFS"
    type="prismatic">
    <origin
      xyz="0.31516 0.050812 -0.047207"
      rpy="2.834 0 3.1416" />
    <parent
      link="base_link" />
    <child
      link="LFS" />
    <axis
      xyz="0 0.3028 -0.95305" />
    <limit
      lower="0"
      upper="0"
      effort="0"
      velocity="0" />
  </joint>
  <link
    name="LFW">
    <inertial>
      <origin
        xyz="-0.008411 1.7347E-18 0"
        rpy="0 0 0" />
      <mass
        value="0.23877" />
      <inertia
        ixx="0.00029907"
        ixy="-3.4096E-22"
        ixz="-2.4198E-21"
        iyy="0.00016737"
        iyz="1.3553E-20"
        izz="0.00016737" />
    </inertial>
    <visual>
      <origin
        xyz="0 0 0"
        rpy="0 0 0" />
      <geometry>
        <mesh
          filename="package://threewheel/meshes/LFW.STL" />
      </geometry>
      <material
        name="">
        <color
          rgba="1 1 1 1" />
      </material>
    </visual>
    <collision>
      <origin
        xyz="0 0 0"
        rpy="0 0 0" />
      <geometry>
        <mesh
          filename="package://threewheel/meshes/LFW.STL" />
      </geometry>
    </collision>
  </link>
  <joint
    name="LFW"
    type="continuous">
    <origin
      xyz="0 -0.018219 -0.039786"
      rpy="-2.5238 0 3.1416" />
    <parent
      link="LFS" />
    <child
      link="LFW" />
    <axis
      xyz="1 0 0" />
    <limit
      effort="3.1"
      velocity="7" />
  </joint>
  <link
    name="RFS">
    <inertial>
      <origin
        xyz="0.072447 -0.0024231 -0.066755"
        rpy="0 0 0" />
      <mass
        value="0.26437" />
      <inertia
        ixx="3.2075E-05"
        ixy="1.4412E-07"
        ixz="6.3085E-08"
        iyy="6.227E-05"
        iyz="-2.0189E-07"
        izz="6.2852E-05" />
    </inertial>
    <visual>
      <origin
        xyz="0 0 0"
        rpy="0 0 0" />
      <geometry>
        <mesh
          filename="package://threewheel/meshes/RFS.STL" />
      </geometry>
      <material
        name="">
        <color
          rgba="0.75294 0.75294 0.75294 1" />
      </material>
    </visual>
    <collision>
      <origin
        xyz="0 0 0"
        rpy="0 0 0" />
      <geometry>
        <mesh
          filename="package://threewheel/meshes/RFS.STL" />
      </geometry>
    </collision>
  </link>
  <joint
    name="RFS"
    type="prismatic">
    <origin
      xyz="-0.10492 0.012128 -0.047207"
      rpy="2.834 0 0" />
    <parent
      link="base_link" />
    <child
      link="RFS" />
    <axis
      xyz="0 0.3028 -0.95305" />
    <limit
      lower="0"
      upper="0"
      effort="0"
      velocity="0" />
  </joint>
  <link
    name="RFW">
    <inertial>
      <origin
        xyz="0.014171 0 0"
        rpy="0 0 0" />
      <mass
        value="0.23877" />
      <inertia
        ixx="0.00029907"
        ixy="-6.0887E-37"
        ixz="-1.8343E-36"
        iyy="0.00016737"
        iyz="-3.2644E-38"
        izz="0.00016737" />
    </inertial>
    <visual>
      <origin
        xyz="0 0 0"
        rpy="0 0 0" />
      <geometry>
        <mesh
          filename="package://threewheel/meshes/RFW.STL" />
      </geometry>
      <material
        name="">
        <color
          rgba="1 1 1 1" />
      </material>
    </visual>
    <collision>
      <origin
        xyz="0 0 0"
        rpy="0 0 0" />
      <geometry>
        <mesh
          filename="package://threewheel/meshes/RFW.STL" />
      </geometry>
    </collision>
  </link>
  <joint
    name="RFW"
    type="continuous">
    <origin
      xyz="0 0.00097405 -0.03369"
      rpy="-1.2632 0 0" />
    <parent
      link="RFS" />
    <child
      link="RFW" />
    <axis
      xyz="1 0 0" />
    <limit
      effort="3.1"
      velocity="7" />
  </joint>
  <link
    name="BC">
    <inertial>
      <origin
        xyz="4.0063E-07 -0.0094793 -5.5511E-17"
        rpy="0 0 0" />
      <mass
        value="0.020987" />
      <inertia
        ixx="7.3202E-06"
        ixy="2.1294E-10"
        ixz="7.9409E-22"
        iyy="3.6659E-06"
        iyz="9.0975E-22"
        izz="8.246E-06" />
    </inertial>
    <visual>
      <origin
        xyz="0 0 0"
        rpy="0 0 0" />
      <geometry>
        <mesh
          filename="package://threewheel/meshes/BC.STL" />
      </geometry>
      <material
        name="">
        <color
          rgba="0.79216 0.81961 0.93333 1" />
      </material>
    </visual>
    <collision>
      <origin
        xyz="0 0 0"
        rpy="0 0 0" />
      <geometry>
        <mesh
          filename="package://threewheel/meshes/BC.STL" />
      </geometry>
    </collision>
  </link>
  <joint
    name="BC"
    type="continuous">
    <origin
      xyz="0.108 0.263000868409068 0"
      rpy="1.5707963267949 0 0.102544806239951" />
    <parent
      link="base_link" />
    <child
      link="BC" />
    <axis
      xyz="0 1 0" />
  </joint>
  <link
    name="BW">
    <inertial>
      <origin
        xyz="1.2669E-05 6.9389E-18 -5.5511E-17"
        rpy="0 0 0" />
      <mass
        value="0.052036" />
      <inertia
        ixx="2.1966E-05"
        ixy="1.2016E-21"
        ixz="-5.7175E-21"
        iyy="1.254E-05"
        iyz="-4.9371E-37"
        izz="1.254E-05" />
    </inertial>
    <visual>
      <origin
        xyz="0 0 0"
        rpy="0 0 0" />
      <geometry>
        <mesh
          filename="package://threewheel/meshes/BW.STL" />
      </geometry>
      <material
        name="">
        <color
          rgba="1 1 1 1" />
      </material>
    </visual>
    <collision>
      <origin
        xyz="0 0 0"
        rpy="0 0 0" />
      <geometry>
        <mesh
          filename="package://threewheel/meshes/BW.STL" />
      </geometry>
    </collision>
  </link>
  <joint
    name="BW"
    type="continuous">
    <origin
      xyz="0 -0.034804 0"
      rpy="0 0 0" />
    <parent
      link="BC" />
    <child
      link="BW" />
    <axis
      xyz="1 0 0" />
  </joint>
</robot>